Traceback (most recent call last):
  File "E:\Users\1127229\AppData\Local\Programs\Python\Python312\Lib\site-packages\jupyter_cache\executors\utils.py", line 58, in single_nb_execution
    executenb(
  File "E:\Users\1127229\AppData\Local\Programs\Python\Python312\Lib\site-packages\nbclient\client.py", line 1314, in execute
    return NotebookClient(nb=nb, resources=resources, km=km, **kwargs).execute()
           ^^^^^^^^^^^^^^^^^^^^^^^^^^^^^^^^^^^^^^^^^^^^^^^^^^^^^^^^^^^^^^^^^^^^^
  File "E:\Users\1127229\AppData\Local\Programs\Python\Python312\Lib\site-packages\jupyter_core\utils\__init__.py", line 172, in wrapped
    return loop.run_until_complete(inner)
           ^^^^^^^^^^^^^^^^^^^^^^^^^^^^^^
  File "E:\Users\1127229\AppData\Local\Programs\Python\Python312\Lib\asyncio\base_events.py", line 684, in run_until_complete
    return future.result()
           ^^^^^^^^^^^^^^^
  File "E:\Users\1127229\AppData\Local\Programs\Python\Python312\Lib\site-packages\nbclient\client.py", line 709, in async_execute
    await self.async_execute_cell(
  File "E:\Users\1127229\AppData\Local\Programs\Python\Python312\Lib\site-packages\nbclient\client.py", line 1062, in async_execute_cell
    await self._check_raise_for_error(cell, cell_index, exec_reply)
  File "E:\Users\1127229\AppData\Local\Programs\Python\Python312\Lib\site-packages\nbclient\client.py", line 918, in _check_raise_for_error
    raise CellExecutionError.from_cell_and_msg(cell, exec_reply_content)
nbclient.exceptions.CellExecutionError: An error occurred while executing the following cell:
------------------
#Comandos m√°gicos
%%timeit 
n = fnsuma(10,10)
------------------

----- stderr -----
UsageError: Line magic function `%%timeit` not found.
------------------



